Workbook

Sheet Start Here
B1: Kinondoni House - Finishing Procurement (China)
B2: Main house only. Doors are made locally (their hardware is on the list). Network/CCTV is not on this list.
B4: SET THESE TWO NUMBERS FIRST
B6: USD/CNY rate (CNY per 1 USD) | C6: 7.1 | D6: Placeholder - update before trusting the USD totals.
B7: Extra tiles for cuts & breakage | C7: 0.12 | D7: Added to every tile quantity. 10-15% is normal; slabs break more and cannot be topped up later.
B9: THE SHEETS
B11: Shopping List | C11: Everything to buy, one line each. Fill in price, supplier and status (yellow). Use the filter arrows to see one category or one room.
B12: By Room | C12: Pick a room, print the page. The supplier packs against it; the site team checks the box against it.
B13: Rooms | C13: Room areas. Correct them after measuring on site - tile quantities update by themselves.
B14: Doors | C14: The 22 locally-made doors. Door hardware quantities update by themselves.
B15: Packing | C15: One line per box. The text to write on each box is created for you. Shows total volume and container size.
B16: Quality Guide | C16: What 'highest quality' means for each item, and where to buy in China.
B18: COLOURS
B20: Yellow = type here
B21: Black = calculated, do not type
B22: Grey italic = optional item
B24: TOTALS
B26: Items on the list | C26: =COUNTIF('Shopping List'!$B$5:$B$316,"?*") -> 212
B27: Items with a price | C27: =COUNTIF('Shopping List'!$I$5:$I$316,">0") -> 0
B28: Total CNY | C28: =SUM('Shopping List'!$J$5:$J$316) -> 0
B29: Total USD | C29: =SUM('Shopping List'!$K$5:$K$316) -> 0
B30: of which optional items (CNY) | C30: =SUMIF('Shopping List'!$D$5:$D$316,"*(optional)*",'Shopping List'!$J$5:$J$316) -> 0
B31: Items received at site | C31: =COUNTIF('Shopping List'!$M$5:$M$316,"Received") -> 0
B32: Boxes packed / received | C32: =Packing!B3&" / "&COUNTIF(Packing!L6:L305,"Y") -> 1 / 0
B34: By category | C34: Items | D34: Total CNY | E34: Total USD | F34: Priced | G34: Received
B35: =Lists!A2 -> Tiles | C35: =COUNTIF('Shopping List'!$C$5:$C$316,B35) -> 45 | D35: =SUMIFS('Shopping List'!$J$5:$J$316,'Shopping List'!$C$5:$C$316,B35) -> 0 | E35: =SUMIFS('Shopping List'!$K$5:$K$316,'Shopping List'!$C$5:$C$316,B35) -> 0 | F35: =COUNTIFS('Shopping List'!$C$5:$C$316,B35,'Shopping List'!$I$5:$I$316,">0") -> 0 | G35: =COUNTIFS('Shopping List'!$C$5:$C$316,B35,'Shopping List'!$M$5:$M$316,"Received") -> 0
B36: =Lists!A3 -> Sanitary | C36: =COUNTIF('Shopping List'!$C$5:$C$316,B36) -> 66 | D36: =SUMIFS('Shopping List'!$J$5:$J$316,'Shopping List'!$C$5:$C$316,B36) -> 0 | E36: =SUMIFS('Shopping List'!$K$5:$K$316,'Shopping List'!$C$5:$C$316,B36) -> 0 | F36: =COUNTIFS('Shopping List'!$C$5:$C$316,B36,'Shopping List'!$I$5:$I$316,">0") -> 0 | G36: =COUNTIFS('Shopping List'!$C$5:$C$316,B36,'Shopping List'!$M$5:$M$316,"Received") -> 0
B37: =Lists!A4 -> Lighting | C37: =COUNTIF('Shopping List'!$C$5:$C$316,B37) -> 13 | D37: =SUMIFS('Shopping List'!$J$5:$J$316,'Shopping List'!$C$5:$C$316,B37) -> 0 | E37: =SUMIFS('Shopping List'!$K$5:$K$316,'Shopping List'!$C$5:$C$316,B37) -> 0 | F37: =COUNTIFS('Shopping List'!$C$5:$C$316,B37,'Shopping List'!$I$5:$I$316,">0") -> 0 | G37: =COUNTIFS('Shopping List'!$C$5:$C$316,B37,'Shopping List'!$M$5:$M$316,"Received") -> 0
B38: =Lists!A5 -> Windows | C38: =COUNTIF('Shopping List'!$C$5:$C$316,B38) -> 7 | D38: =SUMIFS('Shopping List'!$J$5:$J$316,'Shopping List'!$C$5:$C$316,B38) -> 0 | E38: =SUMIFS('Shopping List'!$K$5:$K$316,'Shopping List'!$C$5:$C$316,B38) -> 0 | F38: =COUNTIFS('Shopping List'!$C$5:$C$316,B38,'Shopping List'!$I$5:$I$316,">0") -> 0 | G38: =COUNTIFS('Shopping List'!$C$5:$C$316,B38,'Shopping List'!$M$5:$M$316,"Received") -> 0
B39: =Lists!A6 -> Switches & Sockets | C39: =COUNTIF('Shopping List'!$C$5:$C$316,B39) -> 15 | D39: =SUMIFS('Shopping List'!$J$5:$J$316,'Shopping List'!$C$5:$C$316,B39) -> 0 | E39: =SUMIFS('Shopping List'!$K$5:$K$316,'Shopping List'!$C$5:$C$316,B39) -> 0 | F39: =COUNTIFS('Shopping List'!$C$5:$C$316,B39,'Shopping List'!$I$5:$I$316,">0") -> 0 | G39: =COUNTIFS('Shopping List'!$C$5:$C$316,B39,'Shopping List'!$M$5:$M$316,"Received") -> 0
B40: =Lists!A7 -> Door Hardware | C40: =COUNTIF('Shopping List'!$C$5:$C$316,B40) -> 18 | D40: =SUMIFS('Shopping List'!$J$5:$J$316,'Shopping List'!$C$5:$C$316,B40) -> 0 | E40: =SUMIFS('Shopping List'!$K$5:$K$316,'Shopping List'!$C$5:$C$316,B40) -> 0 | F40: =COUNTIFS('Shopping List'!$C$5:$C$316,B40,'Shopping List'!$I$5:$I$316,">0") -> 0 | G40: =COUNTIFS('Shopping List'!$C$5:$C$316,B40,'Shopping List'!$M$5:$M$316,"Received") -> 0
B41: =Lists!A8 -> Kitchen | C41: =COUNTIF('Shopping List'!$C$5:$C$316,B41) -> 14 | D41: =SUMIFS('Shopping List'!$J$5:$J$316,'Shopping List'!$C$5:$C$316,B41) -> 0 | E41: =SUMIFS('Shopping List'!$K$5:$K$316,'Shopping List'!$C$5:$C$316,B41) -> 0 | F41: =COUNTIFS('Shopping List'!$C$5:$C$316,B41,'Shopping List'!$I$5:$I$316,">0") -> 0 | G41: =COUNTIFS('Shopping List'!$C$5:$C$316,B41,'Shopping List'!$M$5:$M$316,"Received") -> 0
B42: =Lists!A9 -> Dining | C42: =COUNTIF('Shopping List'!$C$5:$C$316,B42) -> 4 | D42: =SUMIFS('Shopping List'!$J$5:$J$316,'Shopping List'!$C$5:$C$316,B42) -> 0 | E42: =SUMIFS('Shopping List'!$K$5:$K$316,'Shopping List'!$C$5:$C$316,B42) -> 0 | F42: =COUNTIFS('Shopping List'!$C$5:$C$316,B42,'Shopping List'!$I$5:$I$316,">0") -> 0 | G42: =COUNTIFS('Shopping List'!$C$5:$C$316,B42,'Shopping List'!$M$5:$M$316,"Received") -> 0
B43: =Lists!A10 -> Living Room | C43: =COUNTIF('Shopping List'!$C$5:$C$316,B43) -> 6 | D43: =SUMIFS('Shopping List'!$J$5:$J$316,'Shopping List'!$C$5:$C$316,B43) -> 0 | E43: =SUMIFS('Shopping List'!$K$5:$K$316,'Shopping List'!$C$5:$C$316,B43) -> 0 | F43: =COUNTIFS('Shopping List'!$C$5:$C$316,B43,'Shopping List'!$I$5:$I$316,">0") -> 0 | G43: =COUNTIFS('Shopping List'!$C$5:$C$316,B43,'Shopping List'!$M$5:$M$316,"Received") -> 0
B44: =Lists!A11 -> Master Bedroom | C44: =COUNTIF('Shopping List'!$C$5:$C$316,B44) -> 10 | D44: =SUMIFS('Shopping List'!$J$5:$J$316,'Shopping List'!$C$5:$C$316,B44) -> 0 | E44: =SUMIFS('Shopping List'!$K$5:$K$316,'Shopping List'!$C$5:$C$316,B44) -> 0 | F44: =COUNTIFS('Shopping List'!$C$5:$C$316,B44,'Shopping List'!$I$5:$I$316,">0") -> 0 | G44: =COUNTIFS('Shopping List'!$C$5:$C$316,B44,'Shopping List'!$M$5:$M$316,"Received") -> 0
B45: =Lists!A12 -> Water Treatment (RO) | C45: =COUNTIF('Shopping List'!$C$5:$C$316,B45) -> 9 | D45: =SUMIFS('Shopping List'!$J$5:$J$316,'Shopping List'!$C$5:$C$316,B45) -> 0 | E45: =SUMIFS('Shopping List'!$K$5:$K$316,'Shopping List'!$C$5:$C$316,B45) -> 0 | F45: =COUNTIFS('Shopping List'!$C$5:$C$316,B45,'Shopping List'!$I$5:$I$316,">0") -> 0 | G45: =COUNTIFS('Shopping List'!$C$5:$C$316,B45,'Shopping List'!$M$5:$M$316,"Received") -> 0
B46: =Lists!A13 -> Tools & Spares | C46: =COUNTIF('Shopping List'!$C$5:$C$316,B46) -> 5 | D46: =SUMIFS('Shopping List'!$J$5:$J$316,'Shopping List'!$C$5:$C$316,B46) -> 0 | E46: =SUMIFS('Shopping List'!$K$5:$K$316,'Shopping List'!$C$5:$C$316,B46) -> 0 | F46: =COUNTIFS('Shopping List'!$C$5:$C$316,B46,'Shopping List'!$I$5:$I$316,">0") -> 0 | G46: =COUNTIFS('Shopping List'!$C$5:$C$316,B46,'Shopping List'!$M$5:$M$316,"Received") -> 0
B47: TOTAL | C47: =SUM(C35:C46) -> 212 | D47: =SUM(D35:D46) -> 0 | E47: =SUM(E35:E46) -> 0 | F47: =SUM(F35:F46) -> 0 | G47: =SUM(G35:G46) -> 0
B49: STILL TO CONFIRM
B51: • Cooking fuel: induction or gas (the hob is listed as induction).
...

Sheet Shopping List
A1: Shopping List
A2: Yellow = type here (price, supplier, status). Black = calculated. Click the filter arrows on row 4 to see one category or one room. Add new items in the empty rows at the bottom.
A4: ID | B4: Room | C4: Category | D4: Item | E4: Must-have spec | F4: Size / Finish | G4: Qty | H4: Unit | I4: Price (CNY) | J4: Total CNY | K4: Total USD | L4: Supplier | M4: Status | N4: Notes | O4: _
A5: GF-ENT-01 | B5: GF-ENT - Entrance | C5: Tiles | D5: Floor - big porcelain slab (+ extra % for cuts) | E5: Porcelain slab, rectified, absorption <0.5%, marble-look | F5: 1200 x 2400 mm, satin finish | G5: =ROUNDUP(INDEX(Rooms!$C$5:$C$47,MATCH(B5,Rooms!$A$5:$A$47,0))*(1+'Start Here'!$C$7),0) -> 5 | H5: m² | J5: =IF(OR(I5="",G5=""),"",G5*I5) | K5: =IF(J5="","",J5/'Start Here'!$C$6) | M5: To buy | N5: Qty follows the area on the Rooms sheet (estimated - measure on site) | O5: =IF(B5="","",IF(B5='By Room'!$C$4,COUNTIF($B$5:B5,'By Room'!$C$4),""))
A6: GF-HAL-01 | B6: GF-HAL - Hall & Corridors | C6: Tiles | D6: Floor - big porcelain slab (+ extra % for cuts) | E6: Porcelain slab, rectified, absorption <0.5%, marble-look | F6: 1200 x 2400 mm, satin finish | G6: =ROUNDUP(INDEX(Rooms!$C$5:$C$47,MATCH(B6,Rooms!$A$5:$A$47,0))*(1+'Start Here'!$C$7),0) -> 51 | H6: m² | J6: =IF(OR(I6="",G6=""),"",G6*I6) | K6: =IF(J6="","",J6/'Start Here'!$C$6) | M6: To buy | N6: Qty follows the area on the Rooms sheet (estimated - measure on site) | O6: =IF(B6="","",IF(B6='By Room'!$C$4,COUNTIF($B$5:B6,'By Room'!$C$4),""))
A7: GF-LIV-01 | B7: GF-LIV - Living Room | C7: Tiles | D7: Floor - big porcelain slab (+ extra % for cuts) | E7: Porcelain slab, rectified, absorption <0.5%, marble-look | F7: 1200 x 2400 mm, satin finish | G7: =ROUNDUP(INDEX(Rooms!$C$5:$C$47,MATCH(B7,Rooms!$A$5:$A$47,0))*(1+'Start Here'!$C$7),0) -> 32 | H7: m² | J7: =IF(OR(I7="",G7=""),"",G7*I7) | K7: =IF(J7="","",J7/'Start Here'!$C$6) | M7: To buy | N7: Qty follows the area on the Rooms sheet (estimated - measure on site) | O7: =IF(B7="","",IF(B7='By Room'!$C$4,COUNTIF($B$5:B7,'By Room'!$C$4),""))
A8: GF-DIN-01 | B8: GF-DIN - Dining | C8: Tiles | D8: Floor - big porcelain slab (+ extra % for cuts) | E8: Porcelain slab, rectified, absorption <0.5%, marble-look | F8: 1200 x 2400 mm, satin finish | G8: =ROUNDUP(INDEX(Rooms!$C$5:$C$47,MATCH(B8,Rooms!$A$5:$A$47,0))*(1+'Start Here'!$C$7),0) -> 33 | H8: m² | J8: =IF(OR(I8="",G8=""),"",G8*I8) | K8: =IF(J8="","",J8/'Start Here'!$C$6) | M8: To buy | N8: Qty follows the area on the Rooms sheet (estimated - measure on site) | O8: =IF(B8="","",IF(B8='By Room'!$C$4,COUNTIF($B$5:B8,'By Room'!$C$4),""))
A9: GF-KIT-01 | B9: GF-KIT - Kitchen | C9: Tiles | D9: Floor - big porcelain slab (+ extra % for cuts) | E9: Porcelain slab, rectified, absorption <0.5%, marble-look | F9: 1200 x 2400 mm, satin finish | G9: =ROUNDUP(INDEX(Rooms!$C$5:$C$47,MATCH(B9,Rooms!$A$5:$A$47,0))*(1+'Start Here'!$C$7),0) -> 25 | H9: m² | J9: =IF(OR(I9="",G9=""),"",G9*I9) | K9: =IF(J9="","",J9/'Start Here'!$C$6) | M9: To buy | N9: Qty follows the area on the Rooms sheet (estimated - measure on site) | O9: =IF(B9="","",IF(B9='By Room'!$C$4,COUNTIF($B$5:B9,'By Room'!$C$4),"")) -> 1
A10: GF-KIT-02 | B10: GF-KIT - Kitchen | C10: Tiles | D10: Kitchen backsplash slab (+ extra %) | E10: Sintered stone or porcelain slab matching worktop | F10: 1200 x 2400 mm | G10: =ROUNDUP(INDEX(Rooms!$D$5:$D$47,MATCH(B10,Rooms!$A$5:$A$47,0))*(1+'Start Here'!$C$7),0) -> 7 | H10: m² | J10: =IF(OR(I10="",G10=""),"",G10*I10) | K10: =IF(J10="","",J10/'Start Here'!$C$6) | M10: To buy | N10: Qty follows Rooms sheet | O10: =IF(B10="","",IF(B10='By Room'!$C$4,COUNTIF($B$5:B10,'By Room'!$C$4),"")) -> 2
A11: GF-PAN-01 | B11: GF-PAN - Walk-in Pantry | C11: Tiles | D11: Floor - big porcelain slab (+ extra % for cuts) | E11: Porcelain slab, rectified, absorption <0.5%, marble-look | F11: 1200 x 2400 mm, satin finish | G11: =ROUNDUP(INDEX(Rooms!$C$5:$C$47,MATCH(B11,Rooms!$A$5:$A$47,0))*(1+'Start Here'!$C$7),0) -> 8 | H11: m² | J11: =IF(OR(I11="",G11=""),"",G11*I11) | K11: =IF(J11="","",J11/'Start Here'!$C$6) | M11: To buy | N11: Qty follows the area on the Rooms sheet (estimated - measure on site) | O11: =IF(B11="","",IF(B11='By Room'!$C$4,COUNTIF($B$5:B11,'By Room'!$C$4),""))
A12: GF-STR-01 | B12: GF-STR - Store Room | C12: Tiles | D12: Floor - big porcelain slab (+ extra % for cuts) | E12: Porcelain slab, rectified, absorption <0.5%, marble-look | F12: 1200 x 2400 mm, satin finish | G12: =ROUNDUP(INDEX(Rooms!$C$5:$C$47,MATCH(B12,Rooms!$A$5:$A$47,0))*(1+'Start Here'!$C$7),0) -> 7 | H12: m² | J12: =IF(OR(I12="",G12=""),"",G12*I12) | K12: =IF(J12="","",J12/'Start Here'!$C$6) | M12: To buy | N12: Qty follows the area on the Rooms sheet (estimated - measure on site) | O12: =IF(B12="","",IF(B12='By Room'!$C$4,COUNTIF($B$5:B12,'By Room'!$C$4),""))
A13: GF-OFF-01 | B13: GF-OFF - Home Office | C13: Tiles | D13: Floor - big porcelain slab (+ extra % for cuts) | E13: Porcelain slab, rectified, absorption <0.5%, marble-look | F13: 1200 x 2400 mm, satin finish | G13: =ROUNDUP(INDEX(Rooms!$C$5:$C$47,MATCH(B13,Rooms!$A$5:$A$47,0))*(1+'Start Here'!$C$7),0) -> 9 | H13: m² | J13: =IF(OR(I13="",G13=""),"",G13*I13) | K13: =IF(J13="","",J13/'Start Here'!$C$6) | M13: To buy | N13: Qty follows the area on the Rooms sheet (estimated - measure on site) | O13: =IF(B13="","",IF(B13='By Room'!$C$4,COUNTIF($B$5:B13,'By Room'!$C$4),""))
A14: GF-PRY-01 | B14: GF-PRY - Prayer Room | C14: Tiles | D14: Floor - big porcelain slab (+ extra % for cuts) | E14: Porcelain slab, rectified, absorption <0.5%, marble-look | F14: 1200 x 2400 mm, satin finish | G14: =ROUNDUP(INDEX(Rooms!$C$5:$C$47,MATCH(B14,Rooms!$A$5:$A$47,0))*(1+'Start Here'!$C$7),0) -> 10 | H14: m² | J14: =IF(OR(I14="",G14=""),"",G14*I14) | K14: =IF(J14="","",J14/'Start Here'!$C$6) | M14: To buy | N14: Qty follows the area on the Rooms sheet (estimated - measure on site) | O14: =IF(B14="","",IF(B14='By Room'!$C$4,COUNTIF($B$5:B14,'By Room'!$C$4),""))
A15: GF-GBR-01 | B15: GF-GBR - Guest Bedroom | C15: Tiles | D15: Floor - big porcelain slab (+ extra % for cuts) | E15: Porcelain slab, rectified, absorption <0.5%, marble-look | F15: 1200 x 2400 mm, satin finish | G15: =ROUNDUP(INDEX(Rooms!$C$5:$C$47,MATCH(B15,Rooms!$A$5:$A$47,0))*(1+'Start Here'!$C$7),0) -> 19 | H15: m² | J15: =IF(OR(I15="",G15=""),"",G15*I15) | K15: =IF(J15="","",J15/'Start Here'!$C$6) | M15: To buy | N15: Qty follows the area on the Rooms sheet (estimated - measure on site) | O15: =IF(B15="","",IF(B15='By Room'!$C$4,COUNTIF($B$5:B15,'By Room'!$C$4),""))
A16: GF-GBA-01 | B16: GF-GBA - Guest Bathroom | C16: Tiles | D16: Bathroom floor - anti-slip (+ extra %) | E16: Porcelain R11 anti-slip, matt | F16: 600 x 1200 mm, matt | G16: =ROUNDUP(INDEX(Rooms!$C$5:$C$47,MATCH(B16,Rooms!$A$5:$A$47,0))*(1+'Start Here'!$C$7),0) -> 7 | H16: m² | J16: =IF(OR(I16="",G16=""),"",G16*I16) | K16: =IF(J16="","",J16/'Start Here'!$C$6) | M16: To buy | N16: Qty follows Rooms sheet | O16: =IF(B16="","",IF(B16='By Room'!$C$4,COUNTIF($B$5:B16,'By Room'!$C$4),""))
A17: GF-GBA-02 | B17: GF-GBA - Guest Bathroom | C17: Tiles | D17: Bathroom walls - full-height slab (+ extra %) | E17: Porcelain wall slab, floor to ceiling | F17: 1200 x 2400 mm, satin | G17: =ROUNDUP(INDEX(Rooms!$D$5:$D$47,MATCH(B17,Rooms!$A$5:$A$47,0))*(1+'Start Here'!$C$7),0) -> 31 | H17: m² | J17: =IF(OR(I17="",G17=""),"",G17*I17) | K17: =IF(J17="","",J17/'Start Here'!$C$6) | M17: To buy | N17: Qty follows Rooms sheet (perimeter x 2.7 m) | O17: =IF(B17="","",IF(B17='By Room'!$C$4,COUNTIF($B$5:B17,'By Room'!$C$4),""))
A18: GF-PWC-01 | B18: GF-PWC - Public WC | C18: Tiles | D18: Bathroom floor - anti-slip (+ extra %) | E18: Porcelain R11 anti-slip, matt | F18: 600 x 1200 mm, matt | G18: =ROUNDUP(INDEX(Rooms!$C$5:$C$47,MATCH(B18,Rooms!$A$5:$A$47,0))*(1+'Start Here'!$C$7),0) -> 3 | H18: m² | J18: =IF(OR(I18="",G18=""),"",G18*I18) | K18: =IF(J18="","",J18/'Start Here'!$C$6) | M18: To buy | N18: Qty follows Rooms sheet | O18: =IF(B18="","",IF(B18='By Room'!$C$4,COUNTIF($B$5:B18,'By Room'!$C$4),""))
A19: GF-PWC-02 | B19: GF-PWC - Public WC | C19: Tiles | D19: Bathroom walls - full-height slab (+ extra %) | E19: Porcelain wall slab, floor to ceiling | F19: 1200 x 2400 mm, satin | G19: =ROUNDUP(INDEX(Rooms!$D$5:$D$47,MATCH(B19,Rooms!$A$5:$A$47,0))*(1+'Start Here'!$C$7),0) -> 17 | H19: m² | J19: =IF(OR(I19="",G19=""),"",G19*I19) | K19: =IF(J19="","",J19/'Start Here'!$C$6) | M19: To buy | N19: Qty follows Rooms sheet (perimeter x 2.7 m) | O19: =IF(B19="","",IF(B19='By Room'!$C$4,COUNTIF($B$5:B19,'By Room'!$C$4),""))
A20: GF-VER-01 | B20: GF-VER - Kitchen Verandah | C20: Tiles | D20: Heavy-duty outdoor floor 20 mm (+ extra %) | E20: 20 mm porcelain R11, car-load strength | F20: 600 x 1200 x 20 mm, dark grey | G20: =ROUNDUP(INDEX(Rooms!$C$5:$C$47,MATCH(B20,Rooms!$A$5:$A$47,0))*(1+'Start Here'!$C$7),0) -> 11 | H20: m² | J20: =IF(OR(I20="",G20=""),"",G20*I20) | K20: =IF(J20="","",J20/'Start Here'!$C$6) | M20: To buy | N20: Dark grey to match charcoal driveway pavers | O20: =IF(B20="","",IF(B20='By Room'!$C$4,COUNTIF($B$5:B20,'By Room'!$C$4),""))
A21: GF-PRK-01 | B21: GF-PRK - Carport | C21: Tiles | D21: Heavy-duty outdoor floor 20 mm (+ extra %) | E21: 20 mm porcelain R11, car-load strength | F21: 600 x 1200 x 20 mm, dark grey | G21: =ROUNDUP(INDEX(Rooms!$C$5:$C$47,MATCH(B21,Rooms!$A$5:$A$47,0))*(1+'Start Here'!$C$7),0) -> 36 | H21: m² | J21: =IF(OR(I21="",G21=""),"",G21*I21) | K21: =IF(J21="","",J21/'Start Here'!$C$6) | M21: To buy | N21: Dark grey to match charcoal driveway pavers | O21: =IF(B21="","",IF(B21='By Room'!$C$4,COUNTIF($B$5:B21,'By Room'!$C$4),""))
A22: GF-STA-01 | B22: GF-STA - Stairs Ground to First | C22: Tiles | D22: Stair treads with anti-slip nosing | E22: Porcelain step tread, grooved nosing, same colour as floor | F22: 1200 x 330 mm | G22: 24 | H22: pcs | J22: =IF(OR(I22="",G22=""),"",G22*I22) | K22: =IF(J22="","",J22/'Start Here'!$C$6) | M22: To buy | N22: 21 treads + 3 spare | O22: =IF(B22="","",IF(B22='By Room'!$C$4,COUNTIF($B$5:B22,'By Room'!$C$4),""))
A23: GF-STA-02 | B23: GF-STA - Stairs Ground to First | C23: Tiles | D23: Stair risers | E23: Porcelain riser matching tread | F23: 1200 x 160 mm | G23: 25 | H23: pcs | J23: =IF(OR(I23="",G23=""),"",G23*I23) | K23: =IF(J23="","",J23/'Start Here'!$C$6) | M23: To buy | N23: 22 risers + 3 spare | O23: =IF(B23="","",IF(B23='By Room'!$C$4,COUNTIF($B$5:B23,'By Room'!$C$4),""))
A24: GF-STA-03 | B24: GF-STA - Stairs Ground to First | C24: Tiles | D24: Stair landings (cut from floor slab) | E24: Same slab as floors | F24: 1200 x 2400 mm | G24: 6 | H24: m² | J24: =IF(OR(I24="",G24=""),"",G24*I24) | K24: =IF(J24="","",J24/'Start Here'!$C$6) | M24: To buy | N24: Assumed - measure landings | O24: =IF(B24="","",IF(B24='By Room'!$C$4,COUNTIF($B$5:B24,'By Room'!$C$4),""))
A25: FF-LND-01 | B25: FF-LND - Landing & Corridor | C25: Tiles | D25: Floor - big porcelain slab (+ extra % for cuts) | E25: Porcelain slab, rectified, absorption <0.5%, marble-look | F25: 1200 x 2400 mm, satin finish | G25: =ROUNDUP(INDEX(Rooms!$C$5:$C$47,MATCH(B25,Rooms!$A$5:$A$47,0))*(1+'Start Here'!$C$7),0) -> 40 | H25: m² | J25: =IF(OR(I25="",G25=""),"",G25*I25) | K25: =IF(J25="","",J25/'Start Here'!$C$6) | M25: To buy | N25: Qty follows the area on the Rooms sheet (estimated - measure on site) | O25: =IF(B25="","",IF(B25='By Room'!$C$4,COUNTIF($B$5:B25,'By Room'!$C$4),""))
A26: FF-MBR-01 | B26: FF-MBR - Master Bedroom | C26: Tiles | D26: Floor - big porcelain slab (+ extra % for cuts) | E26: Porcelain slab, rectified, absorption <0.5%, marble-look | F26: 1200 x 2400 mm, satin finish | G26: =ROUNDUP(INDEX(Rooms!$C$5:$C$47,MATCH(B26,Rooms!$A$5:$A$47,0))*(1+'Start Here'!$C$7),0) -> 32 | H26: m² | J26: =IF(OR(I26="",G26=""),"",G26*I26) | K26: =IF(J26="","",J26/'Start Here'!$C$6) | M26: To buy | N26: Qty follows the area on the Rooms sheet (estimated - measure on site) | O26: =IF(B26="","",IF(B26='By Room'!$C$4,COUNTIF($B$5:B26,'By Room'!$C$4),""))
A27: FF-MBA-01 | B27: FF-MBA - Master Bathroom | C27: Tiles | D27: Bathroom floor - anti-slip (+ extra %) | E27: Porcelain R11 anti-slip, matt | F27: 600 x 1200 mm, matt | G27: =ROUNDUP(INDEX(Rooms!$C$5:$C$47,MATCH(B27,Rooms!$A$5:$A$47,0))*(1+'Start Here'!$C$7),0) -> 10 | H27: m² | J27: =IF(OR(I27="",G27=""),"",G27*I27) | K27: =IF(J27="","",J27/'Start Here'!$C$6) | M27: To buy | N27: Qty follows Rooms sheet | O27: =IF(B27="","",IF(B27='By Room'!$C$4,COUNTIF($B$5:B27,'By Room'!$C$4),""))
A28: FF-MBA-02 | B28: FF-MBA - Master Bathroom | C28: Tiles | D28: Bathroom walls - full-height slab (+ extra %) | E28: Porcelain wall slab, floor to ceiling | F28: 1200 x 2400 mm, satin | G28: =ROUNDUP(INDEX(Rooms!$D$5:$D$47,MATCH(B28,Rooms!$A$5:$A$47,0))*(1+'Start Here'!$C$7),0) -> 33 | H28: m² | J28: =IF(OR(I28="",G28=""),"",G28*I28) | K28: =IF(J28="","",J28/'Start Here'!$C$6) | M28: To buy | N28: Qty follows Rooms sheet (perimeter x 2.7 m) | O28: =IF(B28="","",IF(B28='By Room'!$C$4,COUNTIF($B$5:B28,'By Room'!$C$4),""))
A29: FF-CLO-01 | B29: FF-CLO - Master Closet | C29: Tiles | D29: Floor - big porcelain slab (+ extra % for cuts) | E29: Porcelain slab, rectified, absorption <0.5%, marble-look | F29: 1200 x 2400 mm, satin finish | G29: =ROUNDUP(INDEX(Rooms!$C$5:$C$47,MATCH(B29,Rooms!$A$5:$A$47,0))*(1+'Start Here'!$C$7),0) -> 11 | H29: m² | J29: =IF(OR(I29="",G29=""),"",G29*I29) | K29: =IF(J29="","",J29/'Start Here'!$C$6) | M29: To buy | N29: Qty follows the area on the Rooms sheet (estimated - measure on site) | O29: =IF(B29="","",IF(B29='By Room'!$C$4,COUNTIF($B$5:B29,'By Room'!$C$4),""))
A30: FF-BR1-01 | B30: FF-BR1 - Bedroom 1 | C30: Tiles | D30: Floor - big porcelain slab (+ extra % for cuts) | E30: Porcelain slab, rectified, absorption <0.5%, marble-look | F30: 1200 x 2400 mm, satin finish | G30: =ROUNDUP(INDEX(Rooms!$C$5:$C$47,MATCH(B30,Rooms!$A$5:$A$47,0))*(1+'Start Here'!$C$7),0) -> 19 | H30: m² | J30: =IF(OR(I30="",G30=""),"",G30*I30) | K30: =IF(J30="","",J30/'Start Here'!$C$6) | M30: To buy | N30: Qty follows the area on the Rooms sheet (estimated - measure on site) | O30: =IF(B30="","",IF(B30='By Room'!$C$4,COUNTIF($B$5:B30,'By Room'!$C$4),""))
A31: FF-BA1-01 | B31: FF-BA1 - Bathroom 1 | C31: Tiles | D31: Bathroom floor - anti-slip (+ extra %) | E31: Porcelain R11 anti-slip, matt | F31: 600 x 1200 mm, matt | G31: =ROUNDUP(INDEX(Rooms!$C$5:$C$47,MATCH(B31,Rooms!$A$5:$A$47,0))*(1+'Start Here'!$C$7),0) -> 7 | H31: m² | J31: =IF(OR(I31="",G31=""),"",G31*I31) | K31: =IF(J31="","",J31/'Start Here'!$C$6) | M31: To buy | N31: Qty follows Rooms sheet | O31: =IF(B31="","",IF(B31='By Room'!$C$4,COUNTIF($B$5:B31,'By Room'!$C$4),""))
A32: FF-BA1-02 | B32: FF-BA1 - Bathroom 1 | C32: Tiles | D32: Bathroom walls - full-height slab (+ extra %) | E32: Porcelain wall slab, floor to ceiling | F32: 1200 x 2400 mm, satin | G32: =ROUNDUP(INDEX(Rooms!$D$5:$D$47,MATCH(B32,Rooms!$A$5:$A$47,0))*(1+'Start Here'!$C$7),0) -> 31 | H32: m² | J32: =IF(OR(I32="",G32=""),"",G32*I32) | K32: =IF(J32="","",J32/'Start Here'!$C$6) | M32: To buy | N32: Qty follows Rooms sheet (perimeter x 2.7 m) | O32: =IF(B32="","",IF(B32='By Room'!$C$4,COUNTIF($B$5:B32,'By Room'!$C$4),""))
A33: FF-BR2-01 | B33: FF-BR2 - Bedroom 2 | C33: Tiles | D33: Floor - big porcelain slab (+ extra % for cuts) | E33: Porcelain slab, rectified, absorption <0.5%, marble-look | F33: 1200 x 2400 mm, satin finish | G33: =ROUNDUP(INDEX(Rooms!$C$5:$C$47,MATCH(B33,Rooms!$A$5:$A$47,0))*(1+'Start Here'!$C$7),0) -> 17 | H33: m² | J33: =IF(OR(I33="",G33=""),"",G33*I33) | K33: =IF(J33="","",J33/'Start Here'!$C$6) | M33: To buy | N33: Qty follows the area on the Rooms sheet (estimated - measure on site) | O33: =IF(B33="","",IF(B33='By Room'!$C$4,COUNTIF($B$5:B33,'By Room'!$C$4),""))
A34: FF-BA2-01 | B34: FF-BA2 - Bathroom 2 | C34: Tiles | D34: Bathroom floor - anti-slip (+ extra %) | E34: Porcelain R11 anti-slip, matt | F34: 600 x 1200 mm, matt | G34: =ROUNDUP(INDEX(Rooms!$C$5:$C$47,MATCH(B34,Rooms!$A$5:$A$47,0))*(1+'Start Here'!$C$7),0) -> 8 | H34: m² | J34: =IF(OR(I34="",G34=""),"",G34*I34) | K34: =IF(J34="","",J34/'Start Here'!$C$6) | M34: To buy | N34: Qty follows Rooms sheet | O34: =IF(B34="","",IF(B34='By Room'!$C$4,COUNTIF($B$5:B34,'By Room'!$C$4),""))
A35: FF-BA2-02 | B35: FF-BA2 - Bathroom 2 | C35: Tiles | D35: Bathroom walls - full-height slab (+ extra %) | E35: Porcelain wall slab, floor to ceiling | F35: 1200 x 2400 mm, satin | G35: =ROUNDUP(INDEX(Rooms!$D$5:$D$47,MATCH(B35,Rooms!$A$5:$A$47,0))*(1+'Start Here'!$C$7),0) -> 31 | H35: m² | J35: =IF(OR(I35="",G35=""),"",G35*I35) | K35: =IF(J35="","",J35/'Start Here'!$C$6) | M35: To buy | N35: Qty follows Rooms sheet (perimeter x 2.7 m) | O35: =IF(B35="","",IF(B35='By Room'!$C$4,COUNTIF($B$5:B35,'By Room'!$C$4),""))
A36: FF-BR3-01 | B36: FF-BR3 - Bedroom 3 | C36: Tiles | D36: Floor - big porcelain slab (+ extra % for cuts) | E36: Porcelain slab, rectified, absorption <0.5%, marble-look | F36: 1200 x 2400 mm, satin finish | G36: =ROUNDUP(INDEX(Rooms!$C$5:$C$47,MATCH(B36,Rooms!$A$5:$A$47,0))*(1+'Start Here'!$C$7),0) -> 18 | H36: m² | J36: =IF(OR(I36="",G36=""),"",G36*I36) | K36: =IF(J36="","",J36/'Start Here'!$C$6) | M36: To buy | N36: Qty follows the area on the Rooms sheet (estimated - measure on site) | O36: =IF(B36="","",IF(B36='By Room'!$C$4,COUNTIF($B$5:B36,'By Room'!$C$4),""))
A37: FF-BA3-01 | B37: FF-BA3 - Bathroom 3 | C37: Tiles | D37: Bathroom floor - anti-slip (+ extra %) | E37: Porcelain R11 anti-slip, matt | F37: 600 x 1200 mm, matt | G37: =ROUNDUP(INDEX(Rooms!$C$5:$C$47,MATCH(B37,Rooms!$A$5:$A$47,0))*(1+'Start Here'!$C$7),0) -> 5 | H37: m² | J37: =IF(OR(I37="",G37=""),"",G37*I37) | K37: =IF(J37="","",J37/'Start Here'!$C$6) | M37: To buy | N37: Qty follows Rooms sheet | O37: =IF(B37="","",IF(B37='By Room'!$C$4,COUNTIF($B$5:B37,'By Room'!$C$4),""))
A38: FF-BA3-02 | B38: FF-BA3 - Bathroom 3 | C38: Tiles | D38: Bathroom walls - full-height slab (+ extra %) | E38: Porcelain wall slab, floor to ceiling | F38: 1200 x 2400 mm, satin | G38: =ROUNDUP(INDEX(Rooms!$D$5:$D$47,MATCH(B38,Rooms!$A$5:$A$47,0))*(1+'Start Here'!$C$7),0) -> 24 | H38: m² | J38: =IF(OR(I38="",G38=""),"",G38*I38) | K38: =IF(J38="","",J38/'Start Here'!$C$6) | M38: To buy | N38: Qty follows Rooms sheet (perimeter x 2.7 m) | O38: =IF(B38="","",IF(B38='By Room'!$C$4,COUNTIF($B$5:B38,'By Room'!$C$4),""))
A39: FF-FAM-01 | B39: FF-FAM - Family Lounge | C39: Tiles | D39: Floor - big porcelain slab (+ extra % for cuts) | E39: Porcelain slab, rectified, absorption <0.5%, marble-look | F39: 1200 x 2400 mm, satin finish | G39: =ROUNDUP(INDEX(Rooms!$C$5:$C$47,MATCH(B39,Rooms!$A$5:$A$47,0))*(1+'Start Here'!$C$7),0) -> 32 | H39: m² | J39: =IF(OR(I39="",G39=""),"",G39*I39) | K39: =IF(J39="","",J39/'Start Here'!$C$6) | M39: To buy | N39: Qty follows the area on the Rooms sheet (estimated - measure on site) | O39: =IF(B39="","",IF(B39='By Room'!$C$4,COUNTIF($B$5:B39,'By Room'!$C$4),""))
A40: FF-BAL-01 | B40: FF-BAL - Balconies (all 4) | C40: Tiles | D40: Outdoor floor 20 mm (+ extra %) | E40: 20 mm porcelain, R11, UV stable | F40: 600 x 1200 x 20 mm, stone-look | G40: =ROUNDUP(INDEX(Rooms!$C$5:$C$47,MATCH(B40,Rooms!$A$5:$A$47,0))*(1+'Start Here'!$C$7),0) -> 40 | H40: m² | J40: =IF(OR(I40="",G40=""),"",G40*I40) | K40: =IF(J40="","",J40/'Start Here'!$C$6) | M40: To buy | N40: Qty follows Rooms sheet | O40: =IF(B40="","",IF(B40='By Room'!$C$4,COUNTIF($B$5:B40,'By Room'!$C$4),""))
A41: FF-STA-01 | B41: FF-STA - Stairs First to Roof | C41: Tiles | D41: Stair treads with anti-slip nosing | E41: Porcelain step tread, grooved nosing, same colour as floor | F41: 1200 x 330 mm | G41: 24 | H41: pcs | J41: =IF(OR(I41="",G41=""),"",G41*I41) | K41: =IF(J41="","",J41/'Start Here'!$C$6) | M41: To buy | N41: 21 treads + 3 spare | O41: =IF(B41="","",IF(B41='By Room'!$C$4,COUNTIF($B$5:B41,'By Room'!$C$4),""))
...

Sheet By Room
A1: By Room - choose a room, print the page
A2: Give it to the supplier to pack against, and to the site team when the box for that room arrives.
A4: Room: | C4: GF-KIT - Kitchen
A5: Items: | C5: =COUNTIF('Shopping List'!$B$5:$B$316,C4) -> 17 | D5: Total CNY: | E5: =SUMIFS('Shopping List'!$J$5:$J$316,'Shopping List'!$B$5:$B$316,C4) -> 0 | F5: Total USD: | G5: =SUMIFS('Shopping List'!$K$5:$K$316,'Shopping List'!$B$5:$B$316,C4) -> 0 | H5: Received: | I5: =COUNTIFS('Shopping List'!$B$5:$B$316,C4,'Shopping List'!$M$5:$M$316,"Received")&" of "&C5 -> 0 of 17
A7: # | B7: Item | C7: Must-have spec | D7: Size / Finish | E7: Qty | F7: Unit | G7: Price (CNY) | H7: Supplier | I7: Status | J7: Notes
A8: 1 | B8: =IFERROR(IF(INDEX('Shopping List'!$D$5:$D$316,MATCH($A8,'Shopping List'!$O$5:$O$316,0))="","",INDEX('Shopping List'!$D$5:$D$316,MATCH($A8,'Shopping List'!$O$5:$O$316,0))),"") -> Floor - big porcelain slab (+ extra % for cuts) | C8: =IFERROR(IF(INDEX('Shopping List'!$E$5:$E$316,MATCH($A8,'Shopping List'!$O$5:$O$316,0))="","",INDEX('Shopping List'!$E$5:$E$316,MATCH($A8,'Shopping List'!$O$5:$O$316,0))),"") -> Porcelain slab, rectified, absorption <0.5%, marble-look | D8: =IFERROR(IF(INDEX('Shopping List'!$F$5:$F$316,MATCH($A8,'Shopping List'!$O$5:$O$316,0))="","",INDEX('Shopping List'!$F$5:$F$316,MATCH($A8,'Shopping List'!$O$5:$O$316,0))),"") -> 1200 x 2400 mm, satin finish | E8: =IFERROR(IF(INDEX('Shopping List'!$G$5:$G$316,MATCH($A8,'Shopping List'!$O$5:$O$316,0))="","",INDEX('Shopping List'!$G$5:$G$316,MATCH($A8,'Shopping List'!$O$5:$O$316,0))),"") -> 25 | F8: =IFERROR(IF(INDEX('Shopping List'!$H$5:$H$316,MATCH($A8,'Shopping List'!$O$5:$O$316,0))="","",INDEX('Shopping List'!$H$5:$H$316,MATCH($A8,'Shopping List'!$O$5:$O$316,0))),"") -> m² | G8: =IFERROR(IF(INDEX('Shopping List'!$I$5:$I$316,MATCH($A8,'Shopping List'!$O$5:$O$316,0))="","",INDEX('Shopping List'!$I$5:$I$316,MATCH($A8,'Shopping List'!$O$5:$O$316,0))),"") | H8: =IFERROR(IF(INDEX('Shopping List'!$L$5:$L$316,MATCH($A8,'Shopping List'!$O$5:$O$316,0))="","",INDEX('Shopping List'!$L$5:$L$316,MATCH($A8,'Shopping List'!$O$5:$O$316,0))),"") | I8: =IFERROR(IF(INDEX('Shopping List'!$M$5:$M$316,MATCH($A8,'Shopping List'!$O$5:$O$316,0))="","",INDEX('Shopping List'!$M$5:$M$316,MATCH($A8,'Shopping List'!$O$5:$O$316,0))),"") -> To buy | J8: =IFERROR(IF(INDEX('Shopping List'!$N$5:$N$316,MATCH($A8,'Shopping List'!$O$5:$O$316,0))="","",INDEX('Shopping List'!$N$5:$N$316,MATCH($A8,'Shopping List'!$O$5:$O$316,0))),"") -> Qty follows the area on the Rooms sheet (estimated - measure on site)
A9: 2 | B9: =IFERROR(IF(INDEX('Shopping List'!$D$5:$D$316,MATCH($A9,'Shopping List'!$O$5:$O$316,0))="","",INDEX('Shopping List'!$D$5:$D$316,MATCH($A9,'Shopping List'!$O$5:$O$316,0))),"") -> Kitchen backsplash slab (+ extra %) | C9: =IFERROR(IF(INDEX('Shopping List'!$E$5:$E$316,MATCH($A9,'Shopping List'!$O$5:$O$316,0))="","",INDEX('Shopping List'!$E$5:$E$316,MATCH($A9,'Shopping List'!$O$5:$O$316,0))),"") -> Sintered stone or porcelain slab matching worktop | D9: =IFERROR(IF(INDEX('Shopping List'!$F$5:$F$316,MATCH($A9,'Shopping List'!$O$5:$O$316,0))="","",INDEX('Shopping List'!$F$5:$F$316,MATCH($A9,'Shopping List'!$O$5:$O$316,0))),"") -> 1200 x 2400 mm | E9: =IFERROR(IF(INDEX('Shopping List'!$G$5:$G$316,MATCH($A9,'Shopping List'!$O$5:$O$316,0))="","",INDEX('Shopping List'!$G$5:$G$316,MATCH($A9,'Shopping List'!$O$5:$O$316,0))),"") -> 7 | F9: =IFERROR(IF(INDEX('Shopping List'!$H$5:$H$316,MATCH($A9,'Shopping List'!$O$5:$O$316,0))="","",INDEX('Shopping List'!$H$5:$H$316,MATCH($A9,'Shopping List'!$O$5:$O$316,0))),"") -> m² | G9: =IFERROR(IF(INDEX('Shopping List'!$I$5:$I$316,MATCH($A9,'Shopping List'!$O$5:$O$316,0))="","",INDEX('Shopping List'!$I$5:$I$316,MATCH($A9,'Shopping List'!$O$5:$O$316,0))),"") | H9: =IFERROR(IF(INDEX('Shopping List'!$L$5:$L$316,MATCH($A9,'Shopping List'!$O$5:$O$316,0))="","",INDEX('Shopping List'!$L$5:$L$316,MATCH($A9,'Shopping List'!$O$5:$O$316,0))),"") | I9: =IFERROR(IF(INDEX('Shopping List'!$M$5:$M$316,MATCH($A9,'Shopping List'!$O$5:$O$316,0))="","",INDEX('Shopping List'!$M$5:$M$316,MATCH($A9,'Shopping List'!$O$5:$O$316,0))),"") -> To buy | J9: =IFERROR(IF(INDEX('Shopping List'!$N$5:$N$316,MATCH($A9,'Shopping List'!$O$5:$O$316,0))="","",INDEX('Shopping List'!$N$5:$N$316,MATCH($A9,'Shopping List'!$O$5:$O$316,0))),"") -> Qty follows Rooms sheet
A10: 3 | B10: =IFERROR(IF(INDEX('Shopping List'!$D$5:$D$316,MATCH($A10,'Shopping List'!$O$5:$O$316,0))="","",INDEX('Shopping List'!$D$5:$D$316,MATCH($A10,'Shopping List'!$O$5:$O$316,0))),"") -> Pendants over island (optional) | C10: =IFERROR(IF(INDEX('Shopping List'!$E$5:$E$316,MATCH($A10,'Shopping List'!$O$5:$O$316,0))="","",INDEX('Shopping List'!$E$5:$E$316,MATCH($A10,'Shopping List'!$O$5:$O$316,0))),"") -> LED | D10: =IFERROR(IF(INDEX('Shopping List'!$F$5:$F$316,MATCH($A10,'Shopping List'!$O$5:$O$316,0))="","",INDEX('Shopping List'!$F$5:$F$316,MATCH($A10,'Shopping List'!$O$5:$O$316,0))),"") -> Designer to select | E10: =IFERROR(IF(INDEX('Shopping List'!$G$5:$G$316,MATCH($A10,'Shopping List'!$O$5:$O$316,0))="","",INDEX('Shopping List'!$G$5:$G$316,MATCH($A10,'Shopping List'!$O$5:$O$316,0))),"") -> 3 | F10: =IFERROR(IF(INDEX('Shopping List'!$H$5:$H$316,MATCH($A10,'Shopping List'!$O$5:$O$316,0))="","",INDEX('Shopping List'!$H$5:$H$316,MATCH($A10,'Shopping List'!$O$5:$O$316,0))),"") -> pcs | G10: =IFERROR(IF(INDEX('Shopping List'!$I$5:$I$316,MATCH($A10,'Shopping List'!$O$5:$O$316,0))="","",INDEX('Shopping List'!$I$5:$I$316,MATCH($A10,'Shopping List'!$O$5:$O$316,0))),"") | H10: =IFERROR(IF(INDEX('Shopping List'!$L$5:$L$316,MATCH($A10,'Shopping List'!$O$5:$O$316,0))="","",INDEX('Shopping List'!$L$5:$L$316,MATCH($A10,'Shopping List'!$O$5:$O$316,0))),"") | I10: =IFERROR(IF(INDEX('Shopping List'!$M$5:$M$316,MATCH($A10,'Shopping List'!$O$5:$O$316,0))="","",INDEX('Shopping List'!$M$5:$M$316,MATCH($A10,'Shopping List'!$O$5:$O$316,0))),"") -> To buy | J10: =IFERROR(IF(INDEX('Shopping List'!$N$5:$N$316,MATCH($A10,'Shopping List'!$O$5:$O$316,0))="","",INDEX('Shopping List'!$N$5:$N$316,MATCH($A10,'Shopping List'!$O$5:$O$316,0))),"") -> Only if a ceiling point exists over the island
A11: 4 | B11: =IFERROR(IF(INDEX('Shopping List'!$D$5:$D$316,MATCH($A11,'Shopping List'!$O$5:$O$316,0))="","",INDEX('Shopping List'!$D$5:$D$316,MATCH($A11,'Shopping List'!$O$5:$O$316,0))),"") -> Under-cabinet LED strip + profile + driver | C11: =IFERROR(IF(INDEX('Shopping List'!$E$5:$E$316,MATCH($A11,'Shopping List'!$O$5:$O$316,0))="","",INDEX('Shopping List'!$E$5:$E$316,MATCH($A11,'Shopping List'!$O$5:$O$316,0))),"") -> 24V, CRI>90, aluminium profile with diffuser | D11: =IFERROR(IF(INDEX('Shopping List'!$F$5:$F$316,MATCH($A11,'Shopping List'!$O$5:$O$316,0))="","",INDEX('Shopping List'!$F$5:$F$316,MATCH($A11,'Shopping List'!$O$5:$O$316,0))),"") -> 3000K | E11: =IFERROR(IF(INDEX('Shopping List'!$G$5:$G$316,MATCH($A11,'Shopping List'!$O$5:$O$316,0))="","",INDEX('Shopping List'!$G$5:$G$316,MATCH($A11,'Shopping List'!$O$5:$O$316,0))),"") -> 7 | F11: =IFERROR(IF(INDEX('Shopping List'!$H$5:$H$316,MATCH($A11,'Shopping List'!$O$5:$O$316,0))="","",INDEX('Shopping List'!$H$5:$H$316,MATCH($A11,'Shopping List'!$O$5:$O$316,0))),"") -> m | G11: =IFERROR(IF(INDEX('Shopping List'!$I$5:$I$316,MATCH($A11,'Shopping List'!$O$5:$O$316,0))="","",INDEX('Shopping List'!$I$5:$I$316,MATCH($A11,'Shopping List'!$O$5:$O$316,0))),"") | H11: =IFERROR(IF(INDEX('Shopping List'!$L$5:$L$316,MATCH($A11,'Shopping List'!$O$5:$O$316,0))="","",INDEX('Shopping List'!$L$5:$L$316,MATCH($A11,'Shopping List'!$O$5:$O$316,0))),"") | I11: =IFERROR(IF(INDEX('Shopping List'!$M$5:$M$316,MATCH($A11,'Shopping List'!$O$5:$O$316,0))="","",INDEX('Shopping List'!$M$5:$M$316,MATCH($A11,'Shopping List'!$O$5:$O$316,0))),"") -> To buy | J11: =IFERROR(IF(INDEX('Shopping List'!$N$5:$N$316,MATCH($A11,'Shopping List'!$O$5:$O$316,0))="","",INDEX('Shopping List'!$N$5:$N$316,MATCH($A11,'Shopping List'!$O$5:$O$316,0))),"")
A12: 5 | B12: =IFERROR(IF(INDEX('Shopping List'!$D$5:$D$316,MATCH($A12,'Shopping List'!$O$5:$O$316,0))="","",INDEX('Shopping List'!$D$5:$D$316,MATCH($A12,'Shopping List'!$O$5:$O$316,0))),"") -> Base cabinets - L-shape run | C12: =IFERROR(IF(INDEX('Shopping List'!$E$5:$E$316,MATCH($A12,'Shopping List'!$O$5:$O$316,0))="","",INDEX('Shopping List'!$E$5:$E$316,MATCH($A12,'Shopping List'!$O$5:$O$316,0))),"") -> No particleboard/MDF - aluminium honeycomb, stainless or E0 marine-ply carcass; Blum/Hettich soft-close | D12: =IFERROR(IF(INDEX('Shopping List'!$F$5:$F$316,MATCH($A12,'Shopping List'!$O$5:$O$316,0))="","",INDEX('Shopping List'!$F$5:$F$316,MATCH($A12,'Shopping List'!$O$5:$O$316,0))),"") -> 2000 + 4840 mm runs, 600 deep, 900 high | E12: =IFERROR(IF(INDEX('Shopping List'!$G$5:$G$316,MATCH($A12,'Shopping List'!$O$5:$O$316,0))="","",INDEX('Shopping List'!$G$5:$G$316,MATCH($A12,'Shopping List'!$O$5:$O$316,0))),"") -> 1 | F12: =IFERROR(IF(INDEX('Shopping List'!$H$5:$H$316,MATCH($A12,'Shopping List'!$O$5:$O$316,0))="","",INDEX('Shopping List'!$H$5:$H$316,MATCH($A12,'Shopping List'!$O$5:$O$316,0))),"") -> set | G12: =IFERROR(IF(INDEX('Shopping List'!$I$5:$I$316,MATCH($A12,'Shopping List'!$O$5:$O$316,0))="","",INDEX('Shopping List'!$I$5:$I$316,MATCH($A12,'Shopping List'!$O$5:$O$316,0))),"") | H12: =IFERROR(IF(INDEX('Shopping List'!$L$5:$L$316,MATCH($A12,'Shopping List'!$O$5:$O$316,0))="","",INDEX('Shopping List'!$L$5:$L$316,MATCH($A12,'Shopping List'!$O$5:$O$316,0))),"") | I12: =IFERROR(IF(INDEX('Shopping List'!$M$5:$M$316,MATCH($A12,'Shopping List'!$O$5:$O$316,0))="","",INDEX('Shopping List'!$M$5:$M$316,MATCH($A12,'Shopping List'!$O$5:$O$316,0))),"") -> To buy | J12: =IFERROR(IF(INDEX('Shopping List'!$N$5:$N$316,MATCH($A12,'Shopping List'!$O$5:$O$316,0))="","",INDEX('Shopping List'!$N$5:$N$316,MATCH($A12,'Shopping List'!$O$5:$O$316,0))),"") -> Supplier works from drawing A-101 - confirm sink & hob positions
A13: 6 | B13: =IFERROR(IF(INDEX('Shopping List'!$D$5:$D$316,MATCH($A13,'Shopping List'!$O$5:$O$316,0))="","",INDEX('Shopping List'!$D$5:$D$316,MATCH($A13,'Shopping List'!$O$5:$O$316,0))),"") -> Wall cabinets | C13: =IFERROR(IF(INDEX('Shopping List'!$E$5:$E$316,MATCH($A13,'Shopping List'!$O$5:$O$316,0))="","",INDEX('Shopping List'!$E$5:$E$316,MATCH($A13,'Shopping List'!$O$5:$O$316,0))),"") -> No particleboard/MDF - aluminium honeycomb, stainless or E0 marine-ply carcass; Blum/Hettich soft-close | D13: =IFERROR(IF(INDEX('Shopping List'!$F$5:$F$316,MATCH($A13,'Shopping List'!$O$5:$O$316,0))="","",INDEX('Shopping List'!$F$5:$F$316,MATCH($A13,'Shopping List'!$O$5:$O$316,0))),"") -> Per layout, 720-900 high | E13: =IFERROR(IF(INDEX('Shopping List'!$G$5:$G$316,MATCH($A13,'Shopping List'!$O$5:$O$316,0))="","",INDEX('Shopping List'!$G$5:$G$316,MATCH($A13,'Shopping List'!$O$5:$O$316,0))),"") -> 1 | F13: =IFERROR(IF(INDEX('Shopping List'!$H$5:$H$316,MATCH($A13,'Shopping List'!$O$5:$O$316,0))="","",INDEX('Shopping List'!$H$5:$H$316,MATCH($A13,'Shopping List'!$O$5:$O$316,0))),"") -> set | G13: =IFERROR(IF(INDEX('Shopping List'!$I$5:$I$316,MATCH($A13,'Shopping List'!$O$5:$O$316,0))="","",INDEX('Shopping List'!$I$5:$I$316,MATCH($A13,'Shopping List'!$O$5:$O$316,0))),"") | H13: =IFERROR(IF(INDEX('Shopping List'!$L$5:$L$316,MATCH($A13,'Shopping List'!$O$5:$O$316,0))="","",INDEX('Shopping List'!$L$5:$L$316,MATCH($A13,'Shopping List'!$O$5:$O$316,0))),"") | I13: =IFERROR(IF(INDEX('Shopping List'!$M$5:$M$316,MATCH($A13,'Shopping List'!$O$5:$O$316,0))="","",INDEX('Shopping List'!$M$5:$M$316,MATCH($A13,'Shopping List'!$O$5:$O$316,0))),"") -> To buy | J13: =IFERROR(IF(INDEX('Shopping List'!$N$5:$N$316,MATCH($A13,'Shopping List'!$O$5:$O$316,0))="","",INDEX('Shopping List'!$N$5:$N$316,MATCH($A13,'Shopping List'!$O$5:$O$316,0))),"")
A14: 7 | B14: =IFERROR(IF(INDEX('Shopping List'!$D$5:$D$316,MATCH($A14,'Shopping List'!$O$5:$O$316,0))="","",INDEX('Shopping List'!$D$5:$D$316,MATCH($A14,'Shopping List'!$O$5:$O$316,0))),"") -> Tall units (oven/microwave column + fridge housing) | C14: =IFERROR(IF(INDEX('Shopping List'!$E$5:$E$316,MATCH($A14,'Shopping List'!$O$5:$O$316,0))="","",INDEX('Shopping List'!$E$5:$E$316,MATCH($A14,'Shopping List'!$O$5:$O$316,0))),"") -> No particleboard/MDF - aluminium honeycomb, stainless or E0 marine-ply carcass; Blum/Hettich soft-close | D14: =IFERROR(IF(INDEX('Shopping List'!$F$5:$F$316,MATCH($A14,'Shopping List'!$O$5:$O$316,0))="","",INDEX('Shopping List'!$F$5:$F$316,MATCH($A14,'Shopping List'!$O$5:$O$316,0))),"") -> Per layout, ~2400 high | E14: =IFERROR(IF(INDEX('Shopping List'!$G$5:$G$316,MATCH($A14,'Shopping List'!$O$5:$O$316,0))="","",INDEX('Shopping List'!$G$5:$G$316,MATCH($A14,'Shopping List'!$O$5:$O$316,0))),"") -> 1 | F14: =IFERROR(IF(INDEX('Shopping List'!$H$5:$H$316,MATCH($A14,'Shopping List'!$O$5:$O$316,0))="","",INDEX('Shopping List'!$H$5:$H$316,MATCH($A14,'Shopping List'!$O$5:$O$316,0))),"") -> set | G14: =IFERROR(IF(INDEX('Shopping List'!$I$5:$I$316,MATCH($A14,'Shopping List'!$O$5:$O$316,0))="","",INDEX('Shopping List'!$I$5:$I$316,MATCH($A14,'Shopping List'!$O$5:$O$316,0))),"") | H14: =IFERROR(IF(INDEX('Shopping List'!$L$5:$L$316,MATCH($A14,'Shopping List'!$O$5:$O$316,0))="","",INDEX('Shopping List'!$L$5:$L$316,MATCH($A14,'Shopping List'!$O$5:$O$316,0))),"") | I14: =IFERROR(IF(INDEX('Shopping List'!$M$5:$M$316,MATCH($A14,'Shopping List'!$O$5:$O$316,0))="","",INDEX('Shopping List'!$M$5:$M$316,MATCH($A14,'Shopping List'!$O$5:$O$316,0))),"") -> To buy | J14: =IFERROR(IF(INDEX('Shopping List'!$N$5:$N$316,MATCH($A14,'Shopping List'!$O$5:$O$316,0))="","",INDEX('Shopping List'!$N$5:$N$316,MATCH($A14,'Shopping List'!$O$5:$O$316,0))),"") -> Size to chosen appliances
A15: 8 | B15: =IFERROR(IF(INDEX('Shopping List'!$D$5:$D$316,MATCH($A15,'Shopping List'!$O$5:$O$316,0))="","",INDEX('Shopping List'!$D$5:$D$316,MATCH($A15,'Shopping List'!$O$5:$O$316,0))),"") -> Island cabinet with seating overhang | C15: =IFERROR(IF(INDEX('Shopping List'!$E$5:$E$316,MATCH($A15,'Shopping List'!$O$5:$O$316,0))="","",INDEX('Shopping List'!$E$5:$E$316,MATCH($A15,'Shopping List'!$O$5:$O$316,0))),"") -> No particleboard/MDF - aluminium honeycomb, stainless or E0 marine-ply carcass; Blum/Hettich soft-close | D15: =IFERROR(IF(INDEX('Shopping List'!$F$5:$F$316,MATCH($A15,'Shopping List'!$O$5:$O$316,0))="","",INDEX('Shopping List'!$F$5:$F$316,MATCH($A15,'Shopping List'!$O$5:$O$316,0))),"") -> 2300 x 915 mm (consider 2400 x 1000) | E15: =IFERROR(IF(INDEX('Shopping List'!$G$5:$G$316,MATCH($A15,'Shopping List'!$O$5:$O$316,0))="","",INDEX('Shopping List'!$G$5:$G$316,MATCH($A15,'Shopping List'!$O$5:$O$316,0))),"") -> 1 | F15: =IFERROR(IF(INDEX('Shopping List'!$H$5:$H$316,MATCH($A15,'Shopping List'!$O$5:$O$316,0))="","",INDEX('Shopping List'!$H$5:$H$316,MATCH($A15,'Shopping List'!$O$5:$O$316,0))),"") -> set | G15: =IFERROR(IF(INDEX('Shopping List'!$I$5:$I$316,MATCH($A15,'Shopping List'!$O$5:$O$316,0))="","",INDEX('Shopping List'!$I$5:$I$316,MATCH($A15,'Shopping List'!$O$5:$O$316,0))),"") | H15: =IFERROR(IF(INDEX('Shopping List'!$L$5:$L$316,MATCH($A15,'Shopping List'!$O$5:$O$316,0))="","",INDEX('Shopping List'!$L$5:$L$316,MATCH($A15,'Shopping List'!$O$5:$O$316,0))),"") | I15: =IFERROR(IF(INDEX('Shopping List'!$M$5:$M$316,MATCH($A15,'Shopping List'!$O$5:$O$316,0))="","",INDEX('Shopping List'!$M$5:$M$316,MATCH($A15,'Shopping List'!$O$5:$O$316,0))),"") -> To buy | J15: =IFERROR(IF(INDEX('Shopping List'!$N$5:$N$316,MATCH($A15,'Shopping List'!$O$5:$O$316,0))="","",INDEX('Shopping List'!$N$5:$N$316,MATCH($A15,'Shopping List'!$O$5:$O$316,0))),"")
A16: 9 | B16: =IFERROR(IF(INDEX('Shopping List'!$D$5:$D$316,MATCH($A16,'Shopping List'!$O$5:$O$316,0))="","",INDEX('Shopping List'!$D$5:$D$316,MATCH($A16,'Shopping List'!$O$5:$O$316,0))),"") -> Sintered stone worktop (run + island) | C16: =IFERROR(IF(INDEX('Shopping List'!$E$5:$E$316,MATCH($A16,'Shopping List'!$O$5:$O$316,0))="","",INDEX('Shopping List'!$E$5:$E$316,MATCH($A16,'Shopping List'!$O$5:$O$316,0))),"") -> 12-20 mm, mitred edges, cut-outs for sink & hob | D16: =IFERROR(IF(INDEX('Shopping List'!$F$5:$F$316,MATCH($A16,'Shopping List'!$O$5:$O$316,0))="","",INDEX('Shopping List'!$F$5:$F$316,MATCH($A16,'Shopping List'!$O$5:$O$316,0))),"") -> ~7 m² | E16: =IFERROR(IF(INDEX('Shopping List'!$G$5:$G$316,MATCH($A16,'Shopping List'!$O$5:$O$316,0))="","",INDEX('Shopping List'!$G$5:$G$316,MATCH($A16,'Shopping List'!$O$5:$O$316,0))),"") -> 7 | F16: =IFERROR(IF(INDEX('Shopping List'!$H$5:$H$316,MATCH($A16,'Shopping List'!$O$5:$O$316,0))="","",INDEX('Shopping List'!$H$5:$H$316,MATCH($A16,'Shopping List'!$O$5:$O$316,0))),"") -> m² | G16: =IFERROR(IF(INDEX('Shopping List'!$I$5:$I$316,MATCH($A16,'Shopping List'!$O$5:$O$316,0))="","",INDEX('Shopping List'!$I$5:$I$316,MATCH($A16,'Shopping List'!$O$5:$O$316,0))),"") | H16: =IFERROR(IF(INDEX('Shopping List'!$L$5:$L$316,MATCH($A16,'Shopping List'!$O$5:$O$316,0))="","",INDEX('Shopping List'!$L$5:$L$316,MATCH($A16,'Shopping List'!$O$5:$O$316,0))),"") | I16: =IFERROR(IF(INDEX('Shopping List'!$M$5:$M$316,MATCH($A16,'Shopping List'!$O$5:$O$316,0))="","",INDEX('Shopping List'!$M$5:$M$316,MATCH($A16,'Shopping List'!$O$5:$O$316,0))),"") -> To buy | J16: =IFERROR(IF(INDEX('Shopping List'!$N$5:$N$316,MATCH($A16,'Shopping List'!$O$5:$O$316,0))="","",INDEX('Shopping List'!$N$5:$N$316,MATCH($A16,'Shopping List'!$O$5:$O$316,0))),"") -> Template on site recommended
A17: 10 | B17: =IFERROR(IF(INDEX('Shopping List'!$D$5:$D$316,MATCH($A17,'Shopping List'!$O$5:$O$316,0))="","",INDEX('Shopping List'!$D$5:$D$316,MATCH($A17,'Shopping List'!$O$5:$O$316,0))),"") -> Island bar stools | C17: =IFERROR(IF(INDEX('Shopping List'!$E$5:$E$316,MATCH($A17,'Shopping List'!$O$5:$O$316,0))="","",INDEX('Shopping List'!$E$5:$E$316,MATCH($A17,'Shopping List'!$O$5:$O$316,0))),"") -> Counter height, seat ~650 mm | D17: =IFERROR(IF(INDEX('Shopping List'!$F$5:$F$316,MATCH($A17,'Shopping List'!$O$5:$O$316,0))="","",INDEX('Shopping List'!$F$5:$F$316,MATCH($A17,'Shopping List'!$O$5:$O$316,0))),"") -> Designer to select | E17: =IFERROR(IF(INDEX('Shopping List'!$G$5:$G$316,MATCH($A17,'Shopping List'!$O$5:$O$316,0))="","",INDEX('Shopping List'!$G$5:$G$316,MATCH($A17,'Shopping List'!$O$5:$O$316,0))),"") -> 3 | F17: =IFERROR(IF(INDEX('Shopping List'!$H$5:$H$316,MATCH($A17,'Shopping List'!$O$5:$O$316,0))="","",INDEX('Shopping List'!$H$5:$H$316,MATCH($A17,'Shopping List'!$O$5:$O$316,0))),"") -> pcs | G17: =IFERROR(IF(INDEX('Shopping List'!$I$5:$I$316,MATCH($A17,'Shopping List'!$O$5:$O$316,0))="","",INDEX('Shopping List'!$I$5:$I$316,MATCH($A17,'Shopping List'!$O$5:$O$316,0))),"") | H17: =IFERROR(IF(INDEX('Shopping List'!$L$5:$L$316,MATCH($A17,'Shopping List'!$O$5:$O$316,0))="","",INDEX('Shopping List'!$L$5:$L$316,MATCH($A17,'Shopping List'!$O$5:$O$316,0))),"") | I17: =IFERROR(IF(INDEX('Shopping List'!$M$5:$M$316,MATCH($A17,'Shopping List'!$O$5:$O$316,0))="","",INDEX('Shopping List'!$M$5:$M$316,MATCH($A17,'Shopping List'!$O$5:$O$316,0))),"") -> To buy | J17: =IFERROR(IF(INDEX('Shopping List'!$N$5:$N$316,MATCH($A17,'Shopping List'!$O$5:$O$316,0))="","",INDEX('Shopping List'!$N$5:$N$316,MATCH($A17,'Shopping List'!$O$5:$O$316,0))),"")
A18: 11 | B18: =IFERROR(IF(INDEX('Shopping List'!$D$5:$D$316,MATCH($A18,'Shopping List'!$O$5:$O$316,0))="","",INDEX('Shopping List'!$D$5:$D$316,MATCH($A18,'Shopping List'!$O$5:$O$316,0))),"") -> Under-mount double-bowl sink + pull-down mixer | C18: =IFERROR(IF(INDEX('Shopping List'!$E$5:$E$316,MATCH($A18,'Shopping List'!$O$5:$O$316,0))="","",INDEX('Shopping List'!$E$5:$E$316,MATCH($A18,'Shopping List'!$O$5:$O$316,0))),"") -> Sink SUS304 1.2 mm handmade (SUS316 if offered); mixer SUS316L stainless body (not 304, not zinc, not plated brass), ceramic cartridge, PVD finish | D18: =IFERROR(IF(INDEX('Shopping List'!$F$5:$F$316,MATCH($A18,'Shopping List'!$O$5:$O$316,0))="","",INDEX('Shopping List'!$F$5:$F$316,MATCH($A18,'Shopping List'!$O$5:$O$316,0))),"") -> ~860 x 450 mm, PVD gunmetal | E18: =IFERROR(IF(INDEX('Shopping List'!$G$5:$G$316,MATCH($A18,'Shopping List'!$O$5:$O$316,0))="","",INDEX('Shopping List'!$G$5:$G$316,MATCH($A18,'Shopping List'!$O$5:$O$316,0))),"") -> 1 | F18: =IFERROR(IF(INDEX('Shopping List'!$H$5:$H$316,MATCH($A18,'Shopping List'!$O$5:$O$316,0))="","",INDEX('Shopping List'!$H$5:$H$316,MATCH($A18,'Shopping List'!$O$5:$O$316,0))),"") -> set | G18: =IFERROR(IF(INDEX('Shopping List'!$I$5:$I$316,MATCH($A18,'Shopping List'!$O$5:$O$316,0))="","",INDEX('Shopping List'!$I$5:$I$316,MATCH($A18,'Shopping List'!$O$5:$O$316,0))),"") | H18: =IFERROR(IF(INDEX('Shopping List'!$L$5:$L$316,MATCH($A18,'Shopping List'!$O$5:$O$316,0))="","",INDEX('Shopping List'!$L$5:$L$316,MATCH($A18,'Shopping List'!$O$5:$O$316,0))),"") | I18: =IFERROR(IF(INDEX('Shopping List'!$M$5:$M$316,MATCH($A18,'Shopping List'!$O$5:$O$316,0))="","",INDEX('Shopping List'!$M$5:$M$316,MATCH($A18,'Shopping List'!$O$5:$O$316,0))),"") -> To buy | J18: =IFERROR(IF(INDEX('Shopping List'!$N$5:$N$316,MATCH($A18,'Shopping List'!$O$5:$O$316,0))="","",INDEX('Shopping List'!$N$5:$N$316,MATCH($A18,'Shopping List'!$O$5:$O$316,0))),"")
A19: 12 | B19: =IFERROR(IF(INDEX('Shopping List'!$D$5:$D$316,MATCH($A19,'Shopping List'!$O$5:$O$316,0))="","",INDEX('Shopping List'!$D$5:$D$316,MATCH($A19,'Shopping List'!$O$5:$O$316,0))),"") -> Built-in hob 90 cm | C19: =IFERROR(IF(INDEX('Shopping List'!$E$5:$E$316,MATCH($A19,'Shopping List'!$O$5:$O$316,0))="","",INDEX('Shopping List'!$E$5:$E$316,MATCH($A19,'Shopping List'!$O$5:$O$316,0))),"") -> 220-240V 50Hz, UK plug or hard-wired; confirm local service/warranty; induction 5-zone (or gas - CONFIRM) | D19: =IFERROR(IF(INDEX('Shopping List'!$F$5:$F$316,MATCH($A19,'Shopping List'!$O$5:$O$316,0))="","",INDEX('Shopping List'!$F$5:$F$316,MATCH($A19,'Shopping List'!$O$5:$O$316,0))),"") -> 90 cm, black glass | E19: =IFERROR(IF(INDEX('Shopping List'!$G$5:$G$316,MATCH($A19,'Shopping List'!$O$5:$O$316,0))="","",INDEX('Shopping List'!$G$5:$G$316,MATCH($A19,'Shopping List'!$O$5:$O$316,0))),"") -> 1 | F19: =IFERROR(IF(INDEX('Shopping List'!$H$5:$H$316,MATCH($A19,'Shopping List'!$O$5:$O$316,0))="","",INDEX('Shopping List'!$H$5:$H$316,MATCH($A19,'Shopping List'!$O$5:$O$316,0))),"") -> pcs | G19: =IFERROR(IF(INDEX('Shopping List'!$I$5:$I$316,MATCH($A19,'Shopping List'!$O$5:$O$316,0))="","",INDEX('Shopping List'!$I$5:$I$316,MATCH($A19,'Shopping List'!$O$5:$O$316,0))),"") | H19: =IFERROR(IF(INDEX('Shopping List'!$L$5:$L$316,MATCH($A19,'Shopping List'!$O$5:$O$316,0))="","",INDEX('Shopping List'!$L$5:$L$316,MATCH($A19,'Shopping List'!$O$5:$O$316,0))),"") | I19: =IFERROR(IF(INDEX('Shopping List'!$M$5:$M$316,MATCH($A19,'Shopping List'!$O$5:$O$316,0))="","",INDEX('Shopping List'!$M$5:$M$316,MATCH($A19,'Shopping List'!$O$5:$O$316,0))),"") -> To buy | J19: =IFERROR(IF(INDEX('Shopping List'!$N$5:$N$316,MATCH($A19,'Shopping List'!$O$5:$O$316,0))="","",INDEX('Shopping List'!$N$5:$N$316,MATCH($A19,'Shopping List'!$O$5:$O$316,0))),"") -> Cooking fuel not yet confirmed
... A87: 80 | B87: =IFERROR(IF(INDEX('Shopping List'!$D$5:$D$316,MATCH($A87,'Shopping List'!$O$5:$O$316,0))="","",INDEX('Shopping List'!$D$5:$D$316,MATCH($A87,'Shopping List'!$O$5:$O$316,0))),"") | C87: =IFERROR(IF(INDEX('Shopping List'!$E$5:$E$316,MATCH($A87,'Shopping List'!$O$5:$O$316,0))="","",INDEX('Shopping List'!$E$5:$E$316,MATCH($A87,'Shopping List'!$O$5:$O$316,0))),"") | D87: =IFERROR(IF(INDEX('Shopping List'!$F$5:$F$316,MATCH($A87,'Shopping List'!$O$5:$O$316,0))="","",INDEX('Shopping List'!$F$5:$F$316,MATCH($A87,'Shopping List'!$O$5:$O$316,0))),"") | E87: =IFERROR(IF(INDEX('Shopping List'!$G$5:$G$316,MATCH($A87,'Shopping List'!$O$5:$O$316,0))="","",INDEX('Shopping List'!$G$5:$G$316,MATCH($A87,'Shopping List'!$O$5:$O$316,0))),"") | F87: =IFERROR(IF(INDEX('Shopping List'!$H$5:$H$316,MATCH($A87,'Shopping List'!$O$5:$O$316,0))="","",INDEX('Shopping List'!$H$5:$H$316,MATCH($A87,'Shopping List'!$O$5:$O$316,0))),"") | G87: =IFERROR(IF(INDEX('Shopping List'!$I$5:$I$316,MATCH($A87,'Shopping List'!$O$5:$O$316,0))="","",INDEX('Shopping List'!$I$5:$I$316,MATCH($A87,'Shopping List'!$O$5:$O$316,0))),"") | H87: =IFERROR(IF(INDEX('Shopping List'!$L$5:$L$316,MATCH($A87,'Shopping List'!$O$5:$O$316,0))="","",INDEX('Shopping List'!$L$5:$L$316,MATCH($A87,'Shopping List'!$O$5:$O$316,0))),"") | I87: =IFERROR(IF(INDEX('Shopping List'!$M$5:$M$316,MATCH($A87,'Shopping List'!$O$5:$O$316,0))="","",INDEX('Shopping List'!$M$5:$M$316,MATCH($A87,'Shopping List'!$O$5:$O$316,0))),"") | J87: =IFERROR(IF(INDEX('Shopping List'!$N$5:$N$316,MATCH($A87,'Shopping List'!$O$5:$O$316,0))="","",INDEX('Shopping List'!$N$5:$N$316,MATCH($A87,'Shopping List'!$O$5:$O$316,0))),"")

Sheet Rooms
A1: Rooms
A2: Tile quantities on the Shopping List follow the areas here. Areas are estimated from the drawings - correct them after measuring on site.
A4: Room | B4: Floor | C4: Floor area m² | D4: Wall tile m² | E4: Items | F4: Total CNY | G4: Received | H4: Notes
A5: GF-ENT - Entrance | B5: Ground | C5: 4 | E5: =COUNTIF('Shopping List'!$B$5:$B$316,A5) -> 2 | F5: =SUMIFS('Shopping List'!$J$5:$J$316,'Shopping List'!$B$5:$B$316,A5) -> 0 | G5: =COUNTIFS('Shopping List'!$B$5:$B$316,A5,'Shopping List'!$M$5:$M$316,"Received")&" / "&E5 -> 0 / 2 | H5: Main door
A6: GF-HAL - Hall & Corridors | B6: Ground | C6: 45 | E6: =COUNTIF('Shopping List'!$B$5:$B$316,A6) -> 1 | F6: =SUMIFS('Shopping List'!$J$5:$J$316,'Shopping List'!$B$5:$B$316,A6) -> 0 | G6: =COUNTIFS('Shopping List'!$B$5:$B$316,A6,'Shopping List'!$M$5:$M$316,"Received")&" / "&E6 -> 0 / 1 | H6: Central corridor, stair hall
A7: GF-LIV - Living Room | B7: Ground | C7: 28.2 | E7: =COUNTIF('Shopping List'!$B$5:$B$316,A7) -> 8 | F7: =SUMIFS('Shopping List'!$J$5:$J$316,'Shopping List'!$B$5:$B$316,A7) -> 0 | G7: =COUNTIFS('Shopping List'!$B$5:$B$316,A7,'Shopping List'!$M$5:$M$316,"Received")&" / "&E7 -> 0 / 8 | H7: 6.00 x 4.70 m, TV wall
A8: GF-DIN - Dining | B8: Ground | C8: 28.8 | E8: =COUNTIF('Shopping List'!$B$5:$B$316,A8) -> 7 | F8: =SUMIFS('Shopping List'!$J$5:$J$316,'Shopping List'!$B$5:$B$316,A8) -> 0 | G8: =COUNTIFS('Shopping List'!$B$5:$B$316,A8,'Shopping List'!$M$5:$M$316,"Received")&" / "&E8 -> 0 / 7 | H8: 7.73 x 3.72 m, 8 seats
A9: GF-KIT - Kitchen | B9: Ground | C9: 22 | D9: 6 | E9: =COUNTIF('Shopping List'!$B$5:$B$316,A9) -> 17 | F9: =SUMIFS('Shopping List'!$J$5:$J$316,'Shopping List'!$B$5:$B$316,A9) -> 0 | G9: =COUNTIFS('Shopping List'!$B$5:$B$316,A9,'Shopping List'!$M$5:$M$316,"Received")&" / "&E9 -> 0 / 17 | H9: 5.80 x 3.80 m, L-shape + island; wall m² = backsplash
A10: GF-PAN - Walk-in Pantry | B10: Ground | C10: 6.5 | E10: =COUNTIF('Shopping List'!$B$5:$B$316,A10) -> 2 | F10: =SUMIFS('Shopping List'!$J$5:$J$316,'Shopping List'!$B$5:$B$316,A10) -> 0 | G10: =COUNTIFS('Shopping List'!$B$5:$B$316,A10,'Shopping List'!$M$5:$M$316,"Received")&" / "&E10 -> 0 / 2 | H10: 1.70 x 3.80 m
A11: GF-STR - Store Room | B11: Ground | C11: 5.7 | E11: =COUNTIF('Shopping List'!$B$5:$B$316,A11) -> 1 | F11: =SUMIFS('Shopping List'!$J$5:$J$316,'Shopping List'!$B$5:$B$316,A11) -> 0 | G11: =COUNTIFS('Shopping List'!$B$5:$B$316,A11,'Shopping List'!$M$5:$M$316,"Received")&" / "&E11 -> 0 / 1 | H11: 1.50 x 3.80 m
A12: GF-OFF - Home Office | B12: Ground | C12: 7.9 | E12: =COUNTIF('Shopping List'!$B$5:$B$316,A12) -> 1 | F12: =SUMIFS('Shopping List'!$J$5:$J$316,'Shopping List'!$B$5:$B$316,A12) -> 0 | G12: =COUNTIFS('Shopping List'!$B$5:$B$316,A12,'Shopping List'!$M$5:$M$316,"Received")&" / "&E12 -> 0 / 1
A13: GF-PRY - Prayer Room | B13: Ground | C13: 8.5 | E13: =COUNTIF('Shopping List'!$B$5:$B$316,A13) -> 1 | F13: =SUMIFS('Shopping List'!$J$5:$J$316,'Shopping List'!$B$5:$B$316,A13) -> 0 | G13: =COUNTIFS('Shopping List'!$B$5:$B$316,A13,'Shopping List'!$M$5:$M$316,"Received")&" / "&E13 -> 0 / 1
A14: GF-GBR - Guest Bedroom | B14: Ground | C14: 16.2 | E14: =COUNTIF('Shopping List'!$B$5:$B$316,A14) -> 1 | F14: =SUMIFS('Shopping List'!$J$5:$J$316,'Shopping List'!$B$5:$B$316,A14) -> 0 | G14: =COUNTIFS('Shopping List'!$B$5:$B$316,A14,'Shopping List'!$M$5:$M$316,"Received")&" / "&E14 -> 0 / 1 | H14: 4.27 x 3.80 m
A15: GF-GBA - Guest Bathroom | B15: Ground | C15: 6.2 | D15: 26.9 | E15: =COUNTIF('Shopping List'!$B$5:$B$316,A15) -> 12 | F15: =SUMIFS('Shopping List'!$J$5:$J$316,'Shopping List'!$B$5:$B$316,A15) -> 0 | G15: =COUNTIFS('Shopping List'!$B$5:$B$316,A15,'Shopping List'!$M$5:$M$316,"Received")&" / "&E15 -> 0 / 12 | H15: Shower + WC + basin
A16: GF-PWC - Public WC | B16: Ground | C16: 2.5 | D16: 14.8 | E16: =COUNTIF('Shopping List'!$B$5:$B$316,A16) -> 9 | F16: =SUMIFS('Shopping List'!$J$5:$J$316,'Shopping List'!$B$5:$B$316,A16) -> 0 | G16: =COUNTIFS('Shopping List'!$B$5:$B$316,A16,'Shopping List'!$M$5:$M$316,"Received")&" / "&E16 -> 0 / 9 | H16: WC + basin
A17: GF-VER - Kitchen Verandah | B17: Ground | C17: 9 | E17: =COUNTIF('Shopping List'!$B$5:$B$316,A17) -> 1 | F17: =SUMIFS('Shopping List'!$J$5:$J$316,'Shopping List'!$B$5:$B$316,A17) -> 0 | G17: =COUNTIFS('Shopping List'!$B$5:$B$316,A17,'Shopping List'!$M$5:$M$316,"Received")&" / "&E17 -> 0 / 1 | H17: Outdoor
A18: GF-PRK - Carport | B18: Ground | C18: 31.4 | E18: =COUNTIF('Shopping List'!$B$5:$B$316,A18) -> 1 | F18: =SUMIFS('Shopping List'!$J$5:$J$316,'Shopping List'!$B$5:$B$316,A18) -> 0 | G18: =COUNTIFS('Shopping List'!$B$5:$B$316,A18,'Shopping List'!$M$5:$M$316,"Received")&" / "&E18 -> 0 / 1 | H18: 2 cars
A19: GF-STA - Stairs Ground to First | B19: Ground | E19: =COUNTIF('Shopping List'!$B$5:$B$316,A19) -> 3 | F19: =SUMIFS('Shopping List'!$J$5:$J$316,'Shopping List'!$B$5:$B$316,A19) -> 0 | G19: =COUNTIFS('Shopping List'!$B$5:$B$316,A19,'Shopping List'!$M$5:$M$316,"Received")&" / "&E19 -> 0 / 3 | H19: 22 risers, 21 treads
A20: FF-LND - Landing & Corridor | B20: First | C20: 35 | E20: =COUNTIF('Shopping List'!$B$5:$B$316,A20) -> 1 | F20: =SUMIFS('Shopping List'!$J$5:$J$316,'Shopping List'!$B$5:$B$316,A20) -> 0 | G20: =COUNTIFS('Shopping List'!$B$5:$B$316,A20,'Shopping List'!$M$5:$M$316,"Received")&" / "&E20 -> 0 / 1
A21: FF-MBR - Master Bedroom | B21: First | C21: 28.2 | E21: =COUNTIF('Shopping List'!$B$5:$B$316,A21) -> 11 | F21: =SUMIFS('Shopping List'!$J$5:$J$316,'Shopping List'!$B$5:$B$316,A21) -> 0 | G21: =COUNTIFS('Shopping List'!$B$5:$B$316,A21,'Shopping List'!$M$5:$M$316,"Received")&" / "&E21 -> 0 / 11 | H21: 6.00 x 4.70 m
A22: FF-MBA - Master Bathroom | B22: First | C22: 8.6 | D22: 29.1 | E22: =COUNTIF('Shopping List'!$B$5:$B$316,A22) -> 13 | F22: =SUMIFS('Shopping List'!$J$5:$J$316,'Shopping List'!$B$5:$B$316,A22) -> 0 | G22: =COUNTIFS('Shopping List'!$B$5:$B$316,A22,'Shopping List'!$M$5:$M$316,"Received")&" / "&E22 -> 0 / 13 | H22: Bathtub + shower + double basin
A23: FF-CLO - Master Closet | B23: First | C23: 9 | E23: =COUNTIF('Shopping List'!$B$5:$B$316,A23) -> 2 | F23: =SUMIFS('Shopping List'!$J$5:$J$316,'Shopping List'!$B$5:$B$316,A23) -> 0 | G23: =COUNTIFS('Shopping List'!$B$5:$B$316,A23,'Shopping List'!$M$5:$M$316,"Received")&" / "&E23 -> 0 / 2 | H23: 3.00 x 3.00 m walk-in
A24: FF-BR1 - Bedroom 1 | B24: First | C24: 16.7 | E24: =COUNTIF('Shopping List'!$B$5:$B$316,A24) -> 1 | F24: =SUMIFS('Shopping List'!$J$5:$J$316,'Shopping List'!$B$5:$B$316,A24) -> 0 | G24: =COUNTIFS('Shopping List'!$B$5:$B$316,A24,'Shopping List'!$M$5:$M$316,"Received")&" / "&E24 -> 0 / 1 | H24: Tiles only
A25: FF-BA1 - Bathroom 1 | B25: First | C25: 6.1 | D25: 27.6 | E25: =COUNTIF('Shopping List'!$B$5:$B$316,A25) -> 12 | F25: =SUMIFS('Shopping List'!$J$5:$J$316,'Shopping List'!$B$5:$B$316,A25) -> 0 | G25: =COUNTIFS('Shopping List'!$B$5:$B$316,A25,'Shopping List'!$M$5:$M$316,"Received")&" / "&E25 -> 0 / 12
A26: FF-BR2 - Bedroom 2 | B26: First | C26: 15 | E26: =COUNTIF('Shopping List'!$B$5:$B$316,A26) -> 1 | F26: =SUMIFS('Shopping List'!$J$5:$J$316,'Shopping List'!$B$5:$B$316,A26) -> 0 | G26: =COUNTIFS('Shopping List'!$B$5:$B$316,A26,'Shopping List'!$M$5:$M$316,"Received")&" / "&E26 -> 0 / 1 | H26: Tiles only
A27: FF-BA2 - Bathroom 2 | B27: First | C27: 6.7 | D27: 27.6 | E27: =COUNTIF('Shopping List'!$B$5:$B$316,A27) -> 12 | F27: =SUMIFS('Shopping List'!$J$5:$J$316,'Shopping List'!$B$5:$B$316,A27) -> 0 | G27: =COUNTIFS('Shopping List'!$B$5:$B$316,A27,'Shopping List'!$M$5:$M$316,"Received")&" / "&E27 -> 0 / 12
A28: FF-BR3 - Bedroom 3 | B28: First | C28: 15.7 | E28: =COUNTIF('Shopping List'!$B$5:$B$316,A28) -> 1 | F28: =SUMIFS('Shopping List'!$J$5:$J$316,'Shopping List'!$B$5:$B$316,A28) -> 0 | G28: =COUNTIFS('Shopping List'!$B$5:$B$316,A28,'Shopping List'!$M$5:$M$316,"Received")&" / "&E28 -> 0 / 1 | H28: Tiles only
A29: FF-BA3 - Bathroom 3 | B29: First | C29: 4.3 | D29: 21.2 | E29: =COUNTIF('Shopping List'!$B$5:$B$316,A29) -> 12 | F29: =SUMIFS('Shopping List'!$J$5:$J$316,'Shopping List'!$B$5:$B$316,A29) -> 0 | G29: =COUNTIFS('Shopping List'!$B$5:$B$316,A29,'Shopping List'!$M$5:$M$316,"Received")&" / "&E29 -> 0 / 12
